compute005
2
[33mWARN: gym.spaces.Box autodetected dtype as <class 'numpy.float32'>. Please provide explicit dtype.[0m
Box(1, 60, 50)
Box(1, 60, 50)
/home/zihan/anaconda3/envs/exp/lib/python3.6/site-packages/gym/envs/registration.py:14: PkgResourcesDeprecationWarning: Parameters to load are deprecated.  Call .resolve and .require separately.
  result = entry_point.load(False)
[33mWARN: gym.spaces.Box autodetected dtype as <class 'numpy.float32'>. Please provide explicit dtype.[0m
Box(1, 60, 50)
/home/zihan/anaconda3/envs/exp/lib/python3.6/site-packages/gym/envs/registration.py:14: PkgResourcesDeprecationWarning: Parameters to load are deprecated.  Call .resolve and .require separately.
  result = entry_point.load(False)
Process Process-1:
Traceback (most recent call last):
  File "/home/zihan/anaconda3/envs/exp/lib/python3.6/multiprocessing/process.py", line 258, in _bootstrap
    self.run()
  File "/home/zihan/anaconda3/envs/exp/lib/python3.6/multiprocessing/process.py", line 93, in run
    self._target(*self._args, **self._kwargs)
  File "/home/zihan/Soft-Decision-Tree/image_based_envs/mp_ppo_gae_discrete_cnn.py", line 179, in run
    s = env.reset()
  File "/home/zihan/Soft-Decision-Tree/image_based_envs/env_wrapper.py", line 86, in reset
    return self.prepro(observation)
  File "/home/zihan/Soft-Decision-Tree/image_based_envs/env_wrapper.py", line 68, in prepro
    I=I[10:190, 10:, self.channel]
IndexError: index 3 is out of bounds for axis 2 with size 3
slurmstepd: error: *** JOB 216912 ON compute005 CANCELLED AT 2020-06-10T10:34:30 ***
/home/zihan/anaconda3/envs/exp/lib/python3.6/multiprocessing/semaphore_tracker.py:143: UserWarning: semaphore_tracker: There appear to be 3 leaked semaphores to clean up at shutdown
  len(cache))
/home/zihan/anaconda3/envs/exp/lib/python3.6/multiprocessing/semaphore_tracker.py:155: UserWarning: semaphore_tracker: '/mp-pmzw0i3e': [Errno 2] No such file or directory
  warnings.warn('semaphore_tracker: %r: %s' % (name, e))
/home/zihan/anaconda3/envs/exp/lib/python3.6/multiprocessing/semaphore_tracker.py:155: UserWarning: semaphore_tracker: '/mp-mkoogris': [Errno 2] No such file or directory
  warnings.warn('semaphore_tracker: %r: %s' % (name, e))
/home/zihan/anaconda3/envs/exp/lib/python3.6/multiprocessing/semaphore_tracker.py:155: UserWarning: semaphore_tracker: '/mp-w87pv4lo': [Errno 2] No such file or directory
  warnings.warn('semaphore_tracker: %r: %s' % (name, e))
